Workbook

Sheet Read Me
A1: Southern Water Corp. Financial Analysis
A11: In this unit, you've learned about the fundamentals of financial analysis spanning revenues, expenses and profitability.
A12: In this case study, we'll seek to unpack these concepts, combining the financial analysis skills you've learned and have you apply this through your budding Excel capabilities!
A13: This case study will emphasise both your use of Pivot Tables as well as your charting capabilities, where you'll use these charts for a PowerPoint presentation you'll create at the end of this analysis!
A14: Good luck and let's get started!
A16: What do the tab colours in this workbook mean?
A17: Throughout the Case Study, we've split this into three sections. As you cover the relevant financial concepts, you'll apply what you've learned in the exercise tabs. The order of completion is below: 1) Revenue Sub Unit - Revenue Analysis 2) Expense Sub Unit - Expense Analysis 3) Profitability Sub Unit - Profitability (EBIT) Analysis
A18: Unpacking the Data Repository Table
A19: The data repository table might look scary at first, but all the data is logically grouped in a manner where the table can be read left-to-right.
A20: We've included an example below to break down how you can interpret this information.
A32: Definitions
A33: We've included a high-level breakdown that explains the different columns you will deal with in the data repository table. Please read through this and familiarise yourself with what these columns mean.
A35: Account Type | B35: This column provides information on whether the dataset is referencing either a Revenue Generating Activity (Revenues) or Cost Generating Activity (Expenses) or Water Actuals (Volume of Water Produced).
A36: Unit | B36: There are three desalination units or plants (facilities) owned by Southern Water Corp. These are the Kootha, Surjek and Jutik desalination units. The Unit column indicates, for that row of data, which Unit it applies towards.
A37: Month | B37: This represents the month that data was calculated for.
A38: Month (Number) | B38: This represents the month in numerical form.
A39: Accounting Code Centre | B39: Every row is mapped to an Accounting Code Centre. Based off the Accounting Code Centre (ACC) and the textual description, we know that all ACC's that mention Sales, are Profit Centres, and all ACC's that mention Costs, are Cost Centres. In Financial Accounting, Revenue Generating Activities are mapped to Profit Centres (i.e. They generate profit), whilst Cost Generating Activities are mapped to Cost Centres (i.e. They generate costs).
A40: Accounting Code Centre Element | B40: An Accounting Code Centre Element (ACCE) is made up of 'elements' which tie into the Accounting Code Centre.
A41: Unit of Measure | B41: Every Row of Data has a Unit of Measure (UoM) associated with this. E.g. Financial data is measured in dollars, whilst Water Production data is measure in Giga-Litres.
A42: Row Data | B42: This is the unique value that is stored for every row entry.
A45: Account Types
A46: Below we've included the breakdown for Account Types Revenues and Expenses to better help you understand how the dataset is all connected. Use this if you're feeling unsure of how to calculate Revenues or Expenses.
A48: Revenues | I48: Expenses

Sheet Data Repository Table
A1: Account Type | B1: Unit | C1: Month | D1: Month (Number) | E1: Accounting Code Centre | F1: Accounting Code Centre Element | G1: Unit of Measure | H1: Values
A2: Revenue | B2: Kootha | C2: 41456 | D2: =MONTH(C2) -> 7 | E2: 001 Private Water Hedge Sales | F2: W-Transact (0211) - Soft | G2: $ | H2: 1473589 | I2: Unit | J2: 46216 | K2: 46247 | L2: 46278 | M2: 46308 | N2: 46339 | O2: 46369 | P2: 46036 | Q2: 46067 | R2: 46095 | S2: 46126 | T2: 46156 | U2: 46187 | V2: Total
A3: Revenue | B3: Kootha | C3: 41487 | D3: =MONTH(C3) -> 8 | E3: 001 Private Water Hedge Sales | F3: W-Transact (0211) - Soft | G3: $ | H3: 1419296.1 | I3: Kootha | J3: 2456292.3 | K3: 918310.89 | L3: 1519674.8 | M3: 1671126.7 | N3: 1867603.7 | O3: 1873668.8 | P3: 2572779.4 | Q3: 2504532 | R3: 2888063.9 | S3: 912936.1 | T3: 702117.95 | U3: -165973.35 | V3: 19721133
A4: Revenue | B4: Kootha | C4: 41518 | D4: =MONTH(C4) -> 9 | E4: 001 Private Water Hedge Sales | F4: W-Transact (0211) - Soft | G4: $ | H4: 1310673.2 | I4: Surjek | J4: 5988499.8 | K4: 943434.1 | L4: 2328952.4 | M4: -3360291.1 | N4: -6192464.3 | O4: 2604017 | P4: 8366591.3 | Q4: 2112457.6 | R4: 4631100.2 | S4: 2132932 | T4: -4294074.8 | U4: 7675096 | V4: 22936250
A5: Revenue | B5: Kootha | C5: 41548 | D5: =MONTH(C5) -> 10 | E5: 001 Private Water Hedge Sales | F5: W-Transact (0211) - Soft | G5: $ | H5: 1301024.7 | I5: Jutik | J5: 4547848.2 | K5: 6542227.6 | L5: 4438176.9 | M5: 4415960.6 | N5: 5589126.6 | O5: 5264580.3 | P5: 8292411.6 | Q5: 8295134.3 | R5: 5460903 | S5: 8279084.2 | T5: 6175874.2 | U5: 5640408.6 | V5: 72941736
A6: Revenue | B6: Kootha | C6: 41579 | D6: =MONTH(C6) -> 11 | E6: 001 Private Water Hedge Sales | F6: W-Transact (0211) - Soft | G6: $ | H6: 1373822.9
A7: Revenue | B7: Kootha | C7: 41609 | D7: =MONTH(C7) -> 12 | E7: 001 Private Water Hedge Sales | F7: W-Transact (0211) - Soft | G7: $ | H7: 1340623
A8: Revenue | B8: Kootha | C8: 41640 | D8: =MONTH(C8) -> 1 | E8: 001 Private Water Hedge Sales | F8: W-Transact (0211) - Soft | G8: $ | H8: 1948962.6
A9: Revenue | B9: Kootha | C9: 41671 | D9: =MONTH(C9) -> 2 | E9: 001 Private Water Hedge Sales | F9: W-Transact (0211) - Soft | G9: $ | H9: 1725161.7
A10: Revenue | B10: Kootha | C10: 41699 | D10: =MONTH(C10) -> 3 | E10: 001 Private Water Hedge Sales | F10: W-Transact (0211) - Soft | G10: $ | H10: 1818208.6
A11: Revenue | B11: Kootha | C11: 41730 | D11: =MONTH(C11) -> 4 | E11: 001 Private Water Hedge Sales | F11: W-Transact (0211) - Soft | G11: $ | H11: 1328501.7
A12: Revenue | B12: Kootha | C12: 41760 | D12: =MONTH(C12) -> 5 | E12: 001 Private Water Hedge Sales | F12: W-Transact (0211) - Soft | G12: $ | H12: 1344117.3
A13: Revenue | B13: Kootha | C13: 41791 | D13: =MONTH(C13) -> 6 | E13: 001 Private Water Hedge Sales | F13: W-Transact (0211) - Soft | G13: $ | H13: 1291609.1
A14: Revenue | B14: Kootha | C14: 41456 | D14: =MONTH(C14) -> 7 | E14: 001 Private Water Hedge Sales | F14: W-Transact (0212) - Hard | G14: $ | H14: 1620948
A15: Revenue | B15: Kootha | C15: 41487 | D15: =MONTH(C15) -> 8 | E15: 001 Private Water Hedge Sales | F15: W-Transact (0212) - Hard | G15: $ | H15: 1561225.7
A16: Revenue | B16: Kootha | C16: 41518 | D16: =MONTH(C16) -> 9 | E16: 001 Private Water Hedge Sales | F16: W-Transact (0212) - Hard | G16: $ | H16: 1441740.5
A17: Revenue | B17: Kootha | C17: 41548 | D17: =MONTH(C17) -> 10 | E17: 001 Private Water Hedge Sales | F17: W-Transact (0212) - Hard | G17: $ | H17: 1431127.2
... A373: Expenses | B373: Surjek | C373: 41791 | D373: =MONTH(C373) -> 6 | E373: Labour Costs | F373: Labour-Costs (001) | G373: $ | H373: 1891504.3
A374: Expenses | B374: Jutik | C374: 41456 | D374: 7 | E374: Chemical Costs | F374: Chem-Exp (001) | G374: $ | H374: 1625596.3
A375: Expenses | B375: Jutik | C375: 41487 | D375: 8 | E375: Chemical Costs | F375: Chem-Exp (001) | G375: $ | H375: 1295067.8
A376: Expenses | B376: Jutik | C376: 41518 | D376: 9 | E376: Chemical Costs | F376: Chem-Exp (001) | G376: $ | H376: 1750624.9
A377: Expenses | B377: Jutik | C377: 41548 | D377: 10 | E377: Chemical Costs | F377: Chem-Exp (001) | G377: $ | H377: 1472529.4
A378: Expenses | B378: Jutik | C378: 41579 | D378: 11 | E378: Chemical Costs | F378: Chem-Exp (001) | G378: $ | H378: 1252200.5
A379: Expenses | B379: Jutik | C379: 41609 | D379: 12 | E379: Chemical Costs | F379: Chem-Exp (001) | G379: $ | H379: 1406782.7
A380: Expenses | B380: Jutik | C380: 41640 | D380: 1 | E380: Chemical Costs | F380: Chem-Exp (001) | G380: $ | H380: 1877449.5
A381: Expenses | B381: Jutik | C381: 41671 | D381: 2 | E381: Chemical Costs | F381: Chem-Exp (001) | G381: $ | H381: 1912219.2
A382: Expenses | B382: Jutik | C382: 41699 | D382: 3 | E382: Chemical Costs | F382: Chem-Exp (001) | G382: $ | H382: 2266625.2
A383: Expenses | B383: Jutik | C383: 41730 | D383: 4 | E383: Chemical Costs | F383: Chem-Exp (001) | G383: $ | H383: 2234200.6
A384: Expenses | B384: Jutik | C384: 41760 | D384: 5 | E384: Chemical Costs | F384: Chem-Exp (001) | G384: $ | H384: 2593715.6
A385: Expenses | B385: Jutik | C385: 41791 | D385: 6 | E385: Chemical Costs | F385: Chem-Exp (001) | G385: $ | H385: 2274807.8
... A505: Water Production Actuals | B505: Jutik | C505: 41791 | D505: 6 | E505: None | F505: None | G505: Giga-Litre | H505: 220.38033

Sheet Revenue Analysis
A1: Revenue Analysis - Part I
A2: In Financial Data Analysis, Revenue Analysis speaks primarily to understanding which product(s) generate the most revenues and whether we can identify any aspect of seasonality towards these trends or not.
A3: The importance of this is that we are able to clearly understand which product(s) generate the most revenues and least revenues and this forms the first part of our puzzle.
A4: If a product generates a lot of revenues, but the expenses are greater than the revenues - this isn't a good news story.
A5: However, if the product generates a lot of revenues, and the expenses are well below the revenues - we may have a product which is performing well.
A6: Let's take a look at how Southern Water Corps Revenue Analysis looks like by calculating the Revenues for each of the products and asking ourselves - what does the data tell us?
A7: Let's get started!
A8: Q1. For each of the three Southern Water Corp. Desalination Plants, they produce desalinated water which is then consumed via private, public or residential usage. Please calculate the monthly revenues for Kootha, Surjek and Jutik and put this in the table below.
A9: To do this you should create a Pivot Table in a new worksheet you will call "Pivot Table 1", then copy the results from that Pivot Table into the proper place in the table below.
A10: 1) You will need to create a filter in the Pivot Table that allows you to filter the results to include only the items corresponding to the Revenue Value Driver.
A11: 2) If you structure your Pivot Table correctly and select which rows to subtotal, you should be able to copy and paste everything in one copy and paste.
A12: Unit | B12: Account Type | C12: Accounting Code Centre | D12: Accounting Code Centre Element | E12: 41456 | F12: 41487 | G12: 41518 | H12: 41548 | I12: 41579 | J12: 41609 | K12: 41640 | L12: 41671 | M12: 41699 | N12: 41730 | O12: 41760 | P12: 41791
Q13: Total
A14: Kootha | B14: Revenue | C14: 001 Private Water Hedge Sales | D14: W-Transact (0211) - Soft | E14: 1473589 | F14: 1419296.1 | G14: 1310673.2 | H14: 1301024.7 | I14: 1373822.9 | J14: 1340623 | K14: 1948962.6 | L14: 1725161.7 | M14: 1818208.6 | N14: 1328501.7 | O14: 1344117.3 | P14: 1291609.1 | Q14: 17675590
A15: Kootha | B15: Revenue | C15: 001 Private Water Hedge Sales | D15: W-Transact (0212) - Hard | E15: 1620948 | F15: 1561225.7 | G15: 1441740.5 | H15: 1431127.2 | I15: 1511205.1 | J15: 1474685.3 | K15: 2143858.8 | L15: 1897677.9 | M15: 2000029.5 | N15: 1461351.9 | O15: 1478529 | P15: 1420770 | Q15: 19443149
A16: Kootha | B16: Revenue | C16: 002 Public Sales | D16: W-Transact (0211) - Soft | E16: 567331.78 | F16: 546429 | G16: 504609.19 | H16: 500894.52 | I16: 528921.8 | J16: 516139.87 | K16: 750350.58 | L16: 664187.25 | M16: 700010.32 | N16: 511473.15 | O16: 517485.15 | P16: 497269.52 | Q16: 6805102.1
A17: Kootha | B17: Revenue | C17: 002 Public Sales | D17: W-Transact (0212) - Hard | E17: 955954.05 | F17: 920732.86 | G17: 850266.48 | H17: 844007.27 | I17: 891233.24 | J17: 869695.68 | K17: 1264340.7 | L17: 1119155.5 | M17: 1179517.4 | N17: 861832.25 | O17: 871962.48 | P17: 837899.14 | Q17: 11466597
A18: Kootha | B18: Revenue | C18: 003 Residential Sales | D18: W-Transact (0211) - Soft | E18: 1296758.4 | F18: 1248980.6 | G18: 1153392.4 | H18: 1144901.8 | I18: 1208964.1 | J18: 1179748.3 | K18: 1715087 | L18: 1518142.3 | M18: 1600023.6 | N18: 1169081.5 | O18: 1182823.2 | P18: 1136616 | Q18: 15554519
D19: Total Kootha | E19: 5914581.2 | F19: 5696664.2 | G19: 5260681.8 | H19: 5221955.5 | I19: 5514147.2 | J19: 5380892.2 | K19: 7822599.7 | L19: 6924324.6 | M19: 7297789.4 | N19: 5332240.4 | O19: 5394917.1 | P19: 5184163.9 | Q19: 70944957
A20: Surjek | B20: Revenue | C20: 001 Private Water Hedge Sales | D20: W-Transact (0211) - Soft | E20: 2406673.7 | F20: 2028377 | G20: 2241097.2 | H20: 2104393.5 | I20: 1921236.2 | J20: 2161522.2 | K20: 3104730.2 | L20: 2116798.7 | M20: 2728427.9 | N20: 2259504.9 | O20: 2031569.2 | P20: 2245023.2 | Q20: 27349354
A21: Surjek | B21: Revenue | C21: 001 Private Water Hedge Sales | D21: W-Transact (0212) - Hard | E21: 4813347.5 | F21: 4056754 | G21: 4482194.5 | H21: 4208787 | I21: 3842472.4 | J21: 4323044.3 | K21: 6209460.5 | L21: 4633597.4 | M21: 5456855.8 | N21: 4519009.7 | O21: 4063138.5 | P21: 4490046.5 | Q21: 55098708
A22: Surjek | B22: Revenue | C22: 002 Public Sales | D22: W-Transact (0211) - Soft | E22: 2117872.9 | F22: 1784971.8 | G22: 1972165.6 | H22: 1851866.3 | I22: 1690687.9 | J22: 1902139.5 | K22: 2732162.6 | L22: 2478782.9 | M22: 2401016.5 | N22: 1988364.3 | O22: 1787780.9 | P22: 1975620.4 | Q22: 24683432
A23: Surjek | B23: Revenue | C23: 002 Public Sales | D23: W-Transact (0212) - Hard | E23: 3850678 | F23: 3245403.2 | G23: 3585755.6 | H23: 3367029.6 | I23: 3073978 | J23: 3458435.5 | K23: 4967568.4 | L23: 4506877.9 | M23: 4365484.6 | N23: 4615207.8 | O23: 3250510.8 | P23: 3592037.2 | Q23: 45878966
A24: Surjek | B24: Revenue | C24: 003 Residential Sales | D24: W-Transact (0211) - Soft | E24: 4139478.8 | F24: 3488808.4 | G24: 3854687.3 | H24: 3619556.8 | I24: 3304526.3 | J24: 3717818.1 | K24: 5340136 | L24: 4844893.8 | M24: 4692896 | N24: 4886348.4 | O24: 3494299.1 | P24: 3861440 | Q24: 49244889
D25: Total Surjek | E25: 17328051 | F25: 14604314 | G25: 16135900 | H25: 15151633 | I25: 13832901 | J25: 15562960 | K25: 22354058 | L25: 18580951 | M25: 19644681 | N25: 18268435 | O25: 14627298 | P25: 16164167 | Q25: 2.0225535e+08
A26: Jutik | B26: Revenue | C26: 001 Private Water Hedge Sales | D26: W-Transact (0211) - Soft | E26: 1766228.7 | F26: 1951422.8 | G26: 1699371.2 | H26: 1502189.2 | I26: 1650239.5 | J26: 1406546.1 | K26: 2151540.2 | L26: 2191228.2 | M26: 1965526.6 | N26: 2084911.4 | O26: 2053699.4 | P26: 2197266.9 | Q26: 22620170
A27: Jutik | B27: Revenue | C27: 001 Private Water Hedge Sales | D27: W-Transact (0212) - Hard | E27: 3532457.4 | F27: 3902845.5 | G27: 3398742.5 | H27: 3004378.4 | I27: 3300479 | J27: 2813092.2 | K27: 4303080.4 | L27: 4382456.5 | M27: 3931053.2 | N27: 4169822.7 | O27: 4107398.7 | P27: 4394533.8 | Q27: 45240340
A28: Jutik | B28: Revenue | C28: 002 Public Sales | D28: W-Transact (0211) - Soft | E28: 1554281.3 | F28: 1717252 | G28: 1495446.7 | H28: 1321926.5 | I28: 1452210.8 | J28: 1237760.6 | K28: 1893355.4 | L28: 1928280.8 | M28: 1729663.4 | N28: 1834722 | O28: 1807255.4 | P28: 1933594.9 | Q28: 19905750
A29: Jutik | B29: Revenue | C29: 002 Public Sales | D29: W-Transact (0212) - Hard | E29: 2825966 | F29: 2122276.4 | G29: 3718994 | H29: 3403502.7 | I29: 2640383.2 | J29: 3250473.7 | K29: 3442464.3 | L29: 3505965.2 | M29: 3144842.6 | N29: 3335858.2 | O29: 3285919 | P29: 3515627.1 | Q29: 38192272
A30: Jutik | B30: Revenue | C30: 003 Residential Sales | D30: W-Transact (0211) - Soft | E30: 3037913.4 | F30: 3356447.1 | G30: 2922918.5 | H30: 2583765.4 | I30: 2838412 | J30: 2419259.3 | K30: 3700649.1 | L30: 3768912.5 | M30: 3380705.8 | N30: 3586047.5 | O30: 3032362.9 | P30: 3079299.1 | Q30: 37706693
D31: Total Jutik | E31: 12716847 | F31: 13050244 | G31: 13235473 | H31: 11815762 | I31: 11881724 | J31: 11127132 | K31: 15491089 | L31: 15776843 | M31: 14151792 | N31: 15011362 | O31: 14286635 | P31: 15120322 | Q31: 1.6366523e+08
A34: You've now calculated the Revenues for each of the three desalination plants (Kootha, Surjek and Jutik). This has given you a micro-view of the trends, but let's take a look at the macro-revenue trends and view all this information aggregated together. In the next question, you're aggregating the revenues at the Accounting Code Centre Level, where in the previous question, we went all the way to the Accounting Code Centre Element Level.
A35: Q2. Now, revise , use the SUM Function, calculate the monthly revenues for Kootha, Surjek and Jutik at the Accounting Code Centre Level and put this in the table below. You should make one formula for each cell in column E, then drag it across to populate the remaining columns
A36: Unit | B36: Account Type | C36: Accounting Code Centre | D36: 41456 | E36: 41487 | F36: 41518 | G36: 41548 | H36: 41579 | I36: 41609 | J36: 41640 | K36: 41671 | L36: 41699 | M36: 41730 | N36: 41760 | O36: 41791
P37: Total
A38: Kootha | B38: Revenue | C38: 001 Private Water Hedge Sales | D38: =SUM(E14:E15) -> 3094537 | E38: =SUM(F14:F15) -> 2980521.8 | F38: =SUM(G14:G15) -> 2752413.7 | G38: =SUM(H14:H15) -> 2732151.9 | H38: =SUM(I14:I15) -> 2885028 | I38: =SUM(J14:J15) -> 2815308.4 | J38: =SUM(K14:K15) -> 4092821.4 | K38: =SUM(L14:L15) -> 3622839.6 | ... O38: =SUM(P14:P15) -> 2712379.2 | P38: =SUM(D38:O38) -> 37118739
A39: Kootha | B39: Revenue | C39: 002 Public Sales | D39: =SUM(E16:E17) -> 1523285.8 | E39: =SUM(F16:F17) -> 1467161.9 | F39: =SUM(G16:G17) -> 1354875.7 | G39: =SUM(H16:H17) -> 1344901.8 | H39: =SUM(I16:I17) -> 1420155 | I39: =SUM(J16:J17) -> 1385835.5 | J39: =SUM(K16:K17) -> 2014691.3 | K39: =SUM(L16:L17) -> 1783342.8 | ... O39: =SUM(P16:P17) -> 1335168.7 | P39: =SUM(D39:O39) -> 18271699
A40: Kootha | B40: Revenue | C40: 003 Residential Sales | D40: =SUM(E18) -> 1296758.4 | E40: =SUM(F18) -> 1248980.6 | F40: =SUM(G18) -> 1153392.4 | G40: =SUM(H18) -> 1144901.8 | H40: =SUM(I18) -> 1208964.1 | I40: =SUM(J18) -> 1179748.3 | J40: =SUM(K18) -> 1715087 | K40: =SUM(L18) -> 1518142.3 | ... O40: =SUM(P18) -> 1136616 | P40: =SUM(D40:O40) -> 15554519
A41: Surjek | B41: Revenue | C41: 001 Private Water Hedge Sales | D41: =SUM(E20:E21) -> 7220021.2 | E41: =SUM(F20:F21) -> 6085131 | F41: =SUM(G20:G21) -> 6723291.7 | G41: =SUM(H20:H21) -> 6313180.5 | H41: =SUM(I20:I21) -> 5763708.7 | I41: =SUM(J20:J21) -> 6484566.5 | J41: =SUM(K20:K21) -> 9314190.7 | K41: =SUM(L20:L21) -> 6750396.1 | ... O41: =SUM(P20:P21) -> 6735069.7 | P41: =SUM(D41:O41) -> 82448062
A42: Surjek | B42: Revenue | C42: 002 Public Sales | D42: =SUM(E22:E23) -> 5968550.9 | E42: =SUM(F22:F23) -> 5030375 | F42: =SUM(G22:G23) -> 5557921.2 | G42: =SUM(H22:H23) -> 5218895.9 | H42: =SUM(I22:I23) -> 4764665.8 | I42: =SUM(J22:J23) -> 5360575 | J42: =SUM(K22:K23) -> 7699731 | K42: =SUM(L22:L23) -> 6985660.8 | ... O42: =SUM(P22:P23) -> 5567657.6 | P42: =SUM(D42:O42) -> 70562398
...

Sheet Expenses Analysis
A1: Expenses Analysis - Part II
A2: Expense Analysis speaks primarily to understanding which product(s) are the most expensive to operate and maintain.
A3: Think about this as your personal budget; You want to know exactly where your money is being spent.
A4: As we mentioned in the last section; we've calculated the revenues and know which of our products generate the most revenues at a Unit Level (Kootha, Surjek, Jutik). But it is equally important for us to understand what is our expenses at a unit level. If our expenses outweigh our revenues - this is not a good outcome.If a product generates a lot of revenues, but the expenses are greater than the revenues - this isn't a good news story.
A6: Now let's take a look at how Southern Water Corps Expenses look like by calculating the Expenses for each of the Units and asking ourselves - what does the data tell us?
A7: Note: You may notice some trends with respect to higher costs for those units which produce a specific type of water.
A8: Let's get started!
A10: Q5. For each of the three Southern Water Corp. Desalination Plants, they produce desalinated water which is then consumed via private, public or residential usage. These costs are then aggregated at a Unit Level, separated into Chemical Costs, Facility Costs, Operational Maintenance Costs and Labour Costs. Please calculate the monthly expenses for Kootha, Surjek and Jutik and put this in the table below.
A11: To make fill in this chart, use the same Pivot Table you created previously which should be in the Tab you created "Pivot Table 1" but now filter it to include only the Expense Value Driver
A12: Unit | B12: Account Type | C12: Accounting Code Centre | D12: Accounting Code Centre Element | F12: 41456 | G12: 41487 | H12: 41518 | I12: 41548 | J12: 41579 | K12: 41609 | L12: 41640 | M12: 41671 | N12: 41699 | O12: 41730 | P12: 41760 | Q12: 41791 | R12: Total
A15: Kootha | B15: Expenses | C15: Chemical Costs | D15: Chem-Exp (001) | F15: 593751.84 | G15: 820393.03 | H15: 642291.58 | I15: 609639.97 | J15: 626073.17 | K15: 602153.38 | L15: 1146144 | M15: 964931.84 | N15: 962733.96 | O15: 964825.22 | P15: 1024534.8 | Q15: 1168045.2 | R15: =SUM(F15:Q15) -> 10125518
A16: Kootha | B16: Expenses | C16: Facility Costs | D16: Utility-Exp (002) - Heating | F16: 276807.38 | G16: 382467.61 | H16: 299436.64 | I16: 284214.44 | J16: 291875.6 | K16: 280724.19 | L16: 534332.86 | M16: 449851.67 | N16: 448827.02 | O16: 449801.97 | P16: 477638.59 | Q16: 544543.23 | R16: =SUM(F16:Q16) -> 4720521.2
A17: Kootha | B17: Expenses | C17: Facility Costs | D17: Utility-Exp (002) - Electricity | F17: 415211.08 | G17: 573701.42 | H17: 449154.95 | I17: 426321.66 | J17: 437813.4 | K17: 421086.28 | L17: 801499.29 | M17: 674777.51 | N17: 673240.53 | O17: 674702.95 | P17: 716457.89 | Q17: 816814.84 | R17: =SUM(F17:Q17) -> 7080781.8
A18: Kootha | B18: Expenses | C18: Operational Maintenance Costs | D18: Plant Maintenance (001) | F18: 360688.41 | G18: 498366.89 | H18: 390175.01 | I18: 370340.03 | J18: 380322.76 | K18: 365792.12 | L18: 459526.26 | M18: 386872.44 | N18: 385991.24 | O18: 386829.69 | P18: 410769.19 | Q18: 468307.18 | R18: =SUM(F18:Q18) -> 4863981.2
A19: Kootha | B19: Expenses | C19: Operational Maintenance Costs | D19: Plant Outages (002) | F19: 226478.77 | G19: 312928.05 | H19: 244993.61 | I19: 232539.09 | J19: 238807.31 | K19: 229683.42 | L19: 288539.74 | M19: 242919.9 | N19: 242366.59 | O19: 242893.06 | P19: 257924.84 | Q19: 294053.34 | R19: =SUM(F19:Q19) -> 3054127.7
A20: Kootha | B20: Expenses | C20: Operational Maintenance Costs | D20: Plant Op. Costs (003) | F20: 255837.13 | G20: 353492.8 | H20: 276752.04 | I20: 262683.04 | J20: 269763.82 | K20: 259457.2 | L20: 325943.04 | M20: 274409.52 | N20: 273784.48 | O20: 274379.2 | P20: 291359.54 | Q20: 332171.37 | R20: =SUM(F20:Q20) -> 3450033.2
A21: Kootha | B21: Expenses | C21: Operational Maintenance Costs | D21: Plant Admin Costs (004) | F21: 176150.15 | G21: 243388.48 | H21: 190550.59 | I21: 180863.73 | J21: 185739.02 | K21: 178642.66 | L21: 224419.8 | M21: 188937.7 | N21: 188507.35 | O21: 188916.83 | P21: 200608.21 | Q21: 228708.16 | R21: =SUM(F21:Q21) -> 2375432.7
A22: Kootha | B22: Expenses | C22: Labour Costs | D22: Labour-Costs (001) | F22: 1153364.1 | G22: 1593615.1 | H22: 1247652.6 | I22: 1184226.8 | J22: 1216148.3 | K22: 1169684.1 | L22: 1469415.4 | M22: 1237092.1 | N22: 1234274.3 | O22: 1236955.4 | P22: 1313506.1 | Q22: 1497493.9 | R22: =SUM(F22:Q22) -> 15553428
A23: Total | D23: Total | F23: =SUM(F15:F22) -> 3458288.9 | G23: =SUM(G15:G22) -> 4778353.4 | H23: =SUM(H15:H22) -> 3741007.1 | I23: =SUM(I15:I22) -> 3550828.8 | J23: =SUM(J15:J22) -> 3646543.4 | K23: =SUM(K15:K22) -> 3507223.4 | L23: =SUM(L15:L22) -> 5249820.3 | M23: =SUM(M15:M22) -> 4419792.7 | ... R23: =SUM(R15:R22) -> 51223824
A24: Surjek | B24: Expenses | C24: Chemical Costs | D24: Chem-Exp (001) | F24: 2533034.5 | G24: 3051574.2 | H24: 3084202.8 | I24: 4135202.8 | J24: 4473275.9 | K24: 3464957.9 | L24: 4049642.8 | M24: 4767948.2 | N24: 4346722.8 | O24: 4671541.1 | P24: 5478104.6 | Q24: 2269805.2 | R24: =SUM(F24:Q24) -> 46326013
A25: Surjek | B25: Expenses | C25: Facility Costs | D25: Utility-Exp (002) - Heating | F25: 1266517.3 | G25: 1525787.1 | H25: 1542101.4 | I25: 2067601.4 | J25: 2236637.9 | K25: 1732479 | L25: 2024821.4 | M25: 2383974.1 | N25: 2173361.4 | O25: 2335770.6 | P25: 2739052.3 | Q25: 1134902.6 | R25: =SUM(F25:Q25) -> 23163006
A26: Surjek | B26: Expenses | C26: Facility Costs | D26: Utility-Exp (002) - Electricity | F26: 1055431 | G26: 1271489.2 | H26: 1285084.5 | I26: 1723001.2 | J26: 1863865 | K26: 1443732.5 | L26: 1687351.2 | M26: 1986645.1 | N26: 1811134.5 | O26: 1946475.5 | P26: 2282543.6 | Q26: 945752.15 | R26: =SUM(F26:Q26) -> 19302505
A27: Surjek | B27: Expenses | C27: Operational Maintenance Costs | D27: Plant Maintenance (001) | F27: 996326.91 | G27: 1200285.8 | H27: 1213119.8 | I27: 1626513.1 | J27: 1759488.5 | K27: 1362883.5 | L27: 1592859.5 | M27: 1875393 | N27: 1709711 | O27: 1837472.8 | P27: 2154721.1 | Q27: 892790.03 | R27: =SUM(F27:Q27) -> 18221565
A28: Surjek | B28: Expenses | C28: Operational Maintenance Costs | D28: Plant Outages (002) | F28: 869931.04 | G28: 1048015.4 | H28: 1059221.1 | I28: 1420170.6 | J28: 1536276.6 | K28: 785390.46 | L28: 734335.23 | M28: 864587.94 | N28: 788205.74 | O28: 847106.12 | P28: 993362.97 | Q28: 514489.17 | R28: =SUM(F28:Q28) -> 11461092
A29: Surjek | B29: Expenses | C29: Operational Maintenance Costs | D29: Plant Op. Costs (003) | F29: 921103.46 | G29: 1109663.3 | H29: 1121528.3 | I29: 1503710.1 | J29: 1626645.8 | K29: 831589.9 | L29: 777531.42 | M29: 915446.06 | N29: 834570.78 | O29: 896935.9 | P29: 1051796.1 | Q29: 544753.24 | R29: =SUM(F29:Q29) -> 12135274
A30: Surjek | B30: Expenses | C30: Operational Maintenance Costs | D30: Plant Admin Costs (004) | F30: 498931.04 | G30: 601067.64 | H30: 607494.48 | I30: 814509.64 | J30: 881099.8 | K30: 450444.53 | L30: 421162.85 | M30: 495866.62 | N30: 452059.17 | O30: 485840.28 | P30: 569722.88 | Q30: 295074.67 | R30: =SUM(F30:Q30) -> 6573273.6
A31: Surjek | B31: Expenses | C31: Labour Costs | D31: Labour-Costs (001) | F31: 3198275.9 | G31: 3852997.7 | H31: 3894195.4 | I31: 5221215.6 | J31: 5648075.6 | K31: 2887464.9 | L31: 2699761.9 | M31: 3178632.1 | N31: 2897815.2 | O31: 3114360.8 | P31: 3652069.7 | Q31: 1891504.3 | R31: =SUM(F31:Q31) -> 42136369
D32: Total | F32: =SUM(F24:F31) -> 11339551 | G32: =SUM(G24:G31) -> 13660880 | H32: =SUM(H24:H31) -> 13806948 | I32: =SUM(I24:I31) -> 18511924 | J32: =SUM(J24:J31) -> 20025365 | K32: =SUM(K24:K31) -> 12958943 | L32: =SUM(L24:L31) -> 13987466 | M32: =SUM(M24:M31) -> 16468493 | ... R32: =SUM(R24:R31) -> 1.793191e+08
A33: Jutik | B33: Expenses | C33: Chemical Costs | D33: Chem-Exp (001) | F33: 1625596.3 | G33: 1295067.8 | H33: 1750624.9 | I33: 1472529.4 | J33: 1252200.5 | K33: 1406782.7 | L33: 1877449.5 | M33: 1912219.2 | N33: 2266625.2 | O33: 2234200.6 | P33: 2593715.6 | Q33: 2274807.8 | R33: =SUM(F33:Q33) -> 21961819
A34: Jutik | B34: Expenses | C34: Facility Costs | D34: Utility-Exp (002) - Heating | F34: 895736.76 | G34: 713608.81 | H34: 964630.04 | I34: 811393.74 | J34: 689988.03 | K34: 775165.96 | L34: 1034513 | M34: 888365.67 | N34: 1248956.7 | O34: 680069.7 | P34: 878169.84 | Q34: 1253465.5 | R34: =SUM(F34:Q34) -> 10834064
A35: Jutik | B35: Expenses | C35: Facility Costs | D35: Utility-Exp (002) - Electricity | F35: 829385.89 | G35: 660748.9 | H35: 893175.96 | I35: 751290.5 | J35: 638877.8 | K35: 717746.26 | L35: 957882.4 | M35: 822560.8 | N35: 1156441.4 | O35: 629694.17 | P35: 813120.23 | Q35: 1160616.2 | R35: =SUM(F35:Q35) -> 10031541
A36: Jutik | B36: Expenses | C36: Operational Maintenance Costs | D36: Plant Maintenance (001) | F36: 716589.41 | G36: 570887.05 | H36: 771704.03 | I36: 649115 | J36: 551990.42 | K36: 620132.77 | L36: 827610.39 | M36: 710692.53 | N36: 999165.39 | O36: 544055.76 | P36: 702535.88 | Q36: 1002772.4 | R36: =SUM(F36:Q36) -> 8667251
A37: Jutik | B37: Expenses | C37: Operational Maintenance Costs | D37: Plant Outages (002) | F37: 251329.06 | G37: 200226.94 | H37: 270659.38 | I37: 227663.79 | J37: 193599.33 | K37: 143549.25 | L37: 153261.18 | M37: 131609.73 | N37: 185030.63 | O37: 100751.07 | P37: 130099.24 | Q37: 232123.24 | R37: =SUM(F37:Q37) -> 2219902.8
A38: Jutik | B38: Expenses | C38: Operational Maintenance Costs | D38: Plant Op. Costs (003) | F38: 623296.06 | G38: 496562.81 | H38: 671235.27 | I38: 564606.2 | J38: 480126.35 | K38: 356002.15 | L38: 380087.74 | M38: 326392.13 | N38: 458875.96 | O38: 249862.65 | P38: 322646.11 | Q38: 575665.64 | R38: =SUM(F38:Q38) -> 5505359
A39: Jutik | B39: Expenses | C39: Operational Maintenance Costs | D39: Plant Admin Costs (004) | F39: 211116.41 | G39: 168190.63 | H39: 227353.88 | I39: 191237.58 | J39: 162623.44 | K39: 120581.37 | L39: 128739.39 | M39: 110552.17 | N39: 155425.73 | O39: 84630.897 | P39: 109283.36 | Q39: 194983.52 | R39: =SUM(F39:Q39) -> 1864718.4
A40: Jutik | B40: Expenses | C40: Labour Costs | D40: Labour-Costs (001) | F40: 3015948.7 | G40: 2402723.3 | H40: 3247912.6 | I40: 2731965.5 | J40: 2323192 | K40: 1722591 | L40: 1839134.2 | M40: 2579316.7 | N40: 2220367.5 | O40: 2209012.8 | P40: 2561190.8 | Q40: 2785478.9 | R40: =SUM(F40:Q40) -> 29638834
D41: Total | F41: =SUM(F33:F40) -> 8168998.6 | G41: =SUM(G33:G40) -> 6508016.3 | H41: =SUM(H33:H40) -> 8797296 | I41: =SUM(I33:I40) -> 7399801.7 | J41: =SUM(J33:J40) -> 6292597.9 | K41: =SUM(K33:K40) -> 5862551.5 | L41: =SUM(L33:L40) -> 7198677.8 | M41: =SUM(M33:M40) -> 7481709 | ... R41: =SUM(R33:R40) -> 90723489
A42: You've now calculated the Expenses for each of the three desalination plants (Kootha, Surjek and Jutik). This has given you a micro-view of the trends, but let's take a look at the macro-expenses trends and view all this information aggregated together (Kootha + Surjek + Jutik) and then. Is there any particular trend(s) that we can pick up with respect to which water product(s) have the highest expenses overall?
A43: Q6, Part 1. Using the tables you created in Q5, complete the table below, aggregating all the costs for all units for the respective Accounting Code Centre and Accounting Code Centre Elements. You should be able to create one formula using the SUM function and then drag it across and down to populate the entire table.
B44: Unit | C44: Account Type | D44: Accounting Code Centre | E44: Accounting Code Centre Element | F44: 41456 | G44: 41487 | H44: 41518 | I44: 41548 | J44: 41579 | K44: 41609 | L44: 41640 | M44: 41671 | N44: 41699 | O44: 41730 | P44: 41760 | Q44: 41791
...

Sheet Profitability EBIT Analysis
A1: EBIT Analysis - Part III.
A2: In Financial Data Analysis, EBIT Analysis, also known as Profitability Analysis, speaks primarily to understanding which product(s) are the most cashflow positive.
A3: We're now at the final stage of the puzzle (Woo!); We've got the Revenues. We've got the Expenses. All that is now left is the EBIT and we're done!
A4: Once we subtract our Expenses from our Revenues - we can find out how financially sound Southern Water Corp's Units actually are. Let's take one final look at Southern Water Corp's Data for the 2013 - 2014 Period and find out just how profitable the Unit(s) actually are. Additionally, we'll explore how we can use Ratio's to help us show which Unit(s) are most cost-effective from a Revenue to Expenses perspective.
A6: Let's get started!
A8: EBIT can be simply calculated as Revenues - COGS - Operating Expenses.
A9: In the Southern Water Corp. Case Study, we have opted to wrap up our COGS as part of our overall Expenses to simplify the calculation for you.
A10: Hence, the EBIT you will calculate will simply be: Revenues - Operating Expenses.
A12: Q10. Using the results from Q1 and Q5, populate Part A: the Revenue rows in the table below. Part B: the Expenses rows in the table below. Part C: Calculate EBIT using the formula EBIT = Revenues - Expenses. You should create a formula in Column E and then drag it across
A13: Upon completion of the table, please create two visuals that showcase: 1) Column Chart showing the Total EBIT (Profit) for Kootha, Surjek and Jutik 2) Line Chart showing the Monthly EBIT (Profit) for Kootha, Surjek and Jutik Are there any particular trend(s) that you're able to pick up / take note of with respect to the EBIT?
A14: Unit | E14: 41456 | F14: 41487 | G14: 41518 | H14: 41548 | I14: 41579 | J14: 41609 | K14: 41640 | L14: 41671 | M14: 41699 | N14: 41730 | O14: 41760 | P14: 41791 | Q14: Total
A15: Part A: Calculate Revenues (Use the results of Q2)
A16: Kootha | E16: =SUM('Revenue Analysis'!D38:D40) -> 5914581.2 | F16: =SUM('Revenue Analysis'!E38:E40) -> 5696664.2 | G16: =SUM('Revenue Analysis'!F38:F40) -> 5260681.8 | H16: =SUM('Revenue Analysis'!G38:G40) -> 5221955.5 | I16: =SUM('Revenue Analysis'!H38:H40) -> 5514147.2 | J16: =SUM('Revenue Analysis'!I38:I40) -> 5380892.2 | K16: =SUM('Revenue Analysis'!J38:J40) -> 7822599.7 | L16: =SUM('Revenue Analysis'!K38:K40) -> 6924324.6 | ... P16: =SUM('Revenue Analysis'!O38:O40) -> 5184163.9 | Q16: =SUM(E16:P16) -> 70944957
A17: Surjek | E17: =SUM('Revenue Analysis'!D41:D43) -> 17328051 | F17: =SUM('Revenue Analysis'!E41:E43) -> 14604314 | G17: =SUM('Revenue Analysis'!F41:F43) -> 16135900 | H17: =SUM('Revenue Analysis'!G41:G43) -> 15151633 | I17: =SUM('Revenue Analysis'!H41:H43) -> 13832901 | J17: =SUM('Revenue Analysis'!I41:I43) -> 15562960 | K17: =SUM('Revenue Analysis'!J41:J43) -> 22354058 | L17: =SUM('Revenue Analysis'!K41:K43) -> 18580951 | ... P17: =SUM('Revenue Analysis'!O41:O43) -> 16164167 | Q17: =SUM(E17:P17) -> 2.0225535e+08
A18: Jutik | E18: =SUM('Revenue Analysis'!D44:D46) -> 12716847 | F18: =SUM('Revenue Analysis'!E44:E46) -> 13050244 | G18: =SUM('Revenue Analysis'!F44:F46) -> 13235473 | H18: =SUM('Revenue Analysis'!G44:G46) -> 11815762 | I18: =SUM('Revenue Analysis'!H44:H46) -> 11881724 | J18: =SUM('Revenue Analysis'!I44:I46) -> 11127132 | K18: =SUM('Revenue Analysis'!J44:J46) -> 15491089 | L18: =SUM('Revenue Analysis'!K44:K46) -> 15776843 | ... P18: =SUM('Revenue Analysis'!O44:O46) -> 15120322 | Q18: =SUM(E18:P18) -> 1.6366523e+08
A19: Part B: Calculate Expenses (Use the results of Q5)
A20: Kootha | E20: =SUM('Expenses Analysis'!F15:F22) -> 3458288.9 | F20: =SUM('Expenses Analysis'!G15:G22) -> 4778353.4 | G20: =SUM('Expenses Analysis'!H15:H22) -> 3741007.1 | H20: =SUM('Expenses Analysis'!I15:I22) -> 3550828.8 | I20: =SUM('Expenses Analysis'!J15:J22) -> 3646543.4 | J20: =SUM('Expenses Analysis'!K15:K22) -> 3507223.4 | K20: =SUM('Expenses Analysis'!L15:L22) -> 5249820.3 | L20: =SUM('Expenses Analysis'!M15:M22) -> 4419792.7 | ... P20: =SUM('Expenses Analysis'!Q15:Q22) -> 5350137.2 | Q20: =SUM(E20:P20) -> 51223824
A21: Surjek | E21: =SUM('Expenses Analysis'!F24:F31) -> 11339551 | F21: =SUM('Expenses Analysis'!G24:G31) -> 13660880 | G21: =SUM('Expenses Analysis'!H24:H31) -> 13806948 | H21: =SUM('Expenses Analysis'!I24:I31) -> 18511924 | I21: =SUM('Expenses Analysis'!J24:J31) -> 20025365 | J21: =SUM('Expenses Analysis'!K24:K31) -> 12958943 | K21: =SUM('Expenses Analysis'!L24:L31) -> 13987466 | L21: =SUM('Expenses Analysis'!M24:M31) -> 16468493 | ... P21: =SUM('Expenses Analysis'!Q24:Q31) -> 8489071.3 | Q21: =SUM(E21:P21) -> 1.793191e+08
A22: Jutik | E22: =SUM('Expenses Analysis'!F33:F40) -> 8168998.6 | F22: =SUM('Expenses Analysis'!G33:G40) -> 6508016.3 | G22: =SUM('Expenses Analysis'!H33:H40) -> 8797296 | H22: =SUM('Expenses Analysis'!I33:I40) -> 7399801.7 | I22: =SUM('Expenses Analysis'!J33:J40) -> 6292597.9 | J22: =SUM('Expenses Analysis'!K33:K40) -> 5862551.5 | K22: =SUM('Expenses Analysis'!L33:L40) -> 7198677.8 | L22: =SUM('Expenses Analysis'!M33:M40) -> 7481709 | ... P22: =SUM('Expenses Analysis'!Q33:Q40) -> 9479913.3 | Q22: =SUM(E22:P22) -> 90723489
A23: Part C: Make a formula to calculate EBIT (EBIT = Revenues - Expenses)
A24: Kootha | E24: =SUM(E16-E20) -> 2456292.3 | F24: =SUM(F16-F20) -> 918310.89 | G24: =SUM(G16-G20) -> 1519674.8 | H24: =SUM(H16-H20) -> 1671126.7 | I24: =SUM(I16-I20) -> 1867603.7 | J24: =SUM(J16-J20) -> 1873668.8 | K24: =SUM(K16-K20) -> 2572779.4 | L24: =SUM(L16-L20) -> 2504531.9 | ... Q24: =SUM(Q16-Q20) -> 19721133
A25: Surjek | E25: =SUM(E17-E21) -> 5988499.8 | F25: =SUM(F17-F21) -> 943434.1 | G25: =SUM(G17-G21) -> 2328952.4 | H25: =SUM(H17-H21) -> -3360291.1 | I25: =SUM(I17-I21) -> -6192464.3 | J25: =SUM(J17-J21) -> 2604017 | K25: =SUM(K17-K21) -> 8366591.3 | L25: =SUM(L17-L21) -> 2112457.6 | ... Q25: =SUM(Q17-Q21) -> 22936250
A26: Jutik | E26: =SUM(E18-E22) -> 4547848.2 | F26: =SUM(F18-F22) -> 6542227.6 | G26: =SUM(G18-G22) -> 4438176.9 | H26: =SUM(H18-H22) -> 4415960.6 | I26: =SUM(I18-I22) -> 5589126.6 | J26: =SUM(J18-J22) -> 5264580.3 | K26: =SUM(K18-K22) -> 8292411.6 | L26: =SUM(L18-L22) -> 8295134.3 | ... Q26: =SUM(Q18-Q22) -> 72941736
S35: Jutik is the most stable and consistently profitable unit.
S36: Kootha shows moderate stability but ends the period with weakening profitability.
S37: Surjek is the most unpredictable, with large losses followed by strong rebounds.
A44: It's pretty clear from our EBIT Analysis, that Jutik generates the highest EBIT. However, total EBIT is only part of the story. EBIT Margin is calculated as EBIT / Revenue. It measures on a percentage basis how much of the revenues is left in the company after paying out expenses. Out of Kootha, Surjek and Jutik - which has the highest overall EBIT Margins? Let's close out our EBIT Analysis and find out!
A45: Q11. Calculate the EBIT Margin for each of the Units below by using the results in Q10. Remember EBIT Margin = EBIT / Revenue. Upon completion of the table, please create two visuals that showcase: 1) Column Chart showing the Total EBIT (Profit) for Kootha, Surjek and Jutik 2) Line Chart showing the Monthly EBIT (Profit) for Kootha, Surjek and Jutik What do you conclude?
A47: EBIT Margin
E48: 41456 | F48: 41487 | G48: 41518 | H48: 41548 | I48: 41579 | J48: 41609 | K48: 41640 | L48: 41671 | M48: 41699 | N48: 41730 | O48: 41760 | P48: 41791 | Q48: Total
A49: Unit
A50: Kootha | E50: =E24/E16 -> 0.41529438 | F50: =F24/F16 -> 0.16120151 | G50: =G24/G16 -> 0.28887411 | H50: =H24/H16 -> 0.32001933 | I50: =I24/I16 -> 0.33869313 | J50: =J24/J16 -> 0.34820784 | K50: =K24/K16 -> 0.32889058 | L50: =L24/L16 -> 0.36170054 | ... Q50: =Q24/Q16 -> 0.27797794
A51: Surjek | E51: =E25/E17 -> 0.34559569 | F51: =F25/F17 -> 0.064599684 | G51: =G25/G17 -> 0.14433359 | H51: =H25/H17 -> -0.22177748 | I51: =I25/I17 -> -0.44766202 | J51: =J25/J17 -> 0.16732145 | K51: =K25/K17 -> 0.37427618 | L51: =L25/L17 -> 0.11368942 | ... Q51: =Q25/Q17 -> 0.11340244
A52: Jutik | E52: =E26/E18 -> 0.35762389 | F52: =F26/F18 -> 0.50131075 | G52: =G26/G18 -> 0.33532439 | H52: =H26/H18 -> 0.37373472 | I52: =I26/I18 -> 0.47039692 | J52: =J26/J18 -> 0.47313004 | K52: =K26/K18 -> 0.53530203 | L52: =L26/L18 -> 0.52577909 | ... Q52: =Q26/Q18 -> 0.44567645
A72: Jutik is the most profitable and operationally efficient unit.
A73: Kootha is moderately profitable but shows signs of declining performance.
A74: Surjek carries the highest risk due to extreme volatility and frequent losses

Sheet Pivot Table 1
A4: Sum of Values2 | E4: Month
A5: Unit | B5: Account Type | C5: Accounting Code Centre | D5: Accounting Code Centre Element | E5: 41456 | F5: 41487 | G5: 41518 | H5: 41548 | I5: 41579 | J5: 41609 | K5: 41640 | L5: 41671 | M5: 41699 | N5: 41730 | O5: 41760 | P5: 41791 | Q5: Grand Total
A6: A) Kootha | B6: Expenses | C6: A)Chemical Costs | D6: Chem-Exp (001) | E6: 593751.84 | F6: 820393.03 | G6: 642291.58 | H6: 609639.97 | I6: 626073.17 | J6: 602153.38 | K6: 1146144 | L6: 964931.84 | M6: 962733.96 | N6: 964825.22 | O6: 1024534.8 | P6: 1168045.2 | Q6: 10125518
C7: B) Facility Costs | D7: Utility-Exp (002) - Heating | E7: 276807.38 | F7: 382467.61 | G7: 299436.64 | H7: 284214.44 | I7: 291875.6 | J7: 280724.19 | K7: 534332.86 | L7: 449851.67 | M7: 448827.02 | N7: 449801.97 | O7: 477638.59 | P7: 544543.23 | Q7: 4720521.2
D8: Utility-Exp (002) - Electricity | E8: 415211.08 | F8: 573701.42 | G8: 449154.95 | H8: 426321.66 | I8: 437813.4 | J8: 421086.28 | K8: 801499.29 | L8: 674777.51 | M8: 673240.53 | N8: 674702.95 | O8: 716457.89 | P8: 816814.84 | Q8: 7080781.8
C9: C) Operational Maintenance Costs | D9: Plant Maintenance (001) | E9: 360688.41 | F9: 498366.89 | G9: 390175.01 | H9: 370340.03 | I9: 380322.76 | J9: 365792.12 | K9: 459526.26 | L9: 386872.44 | M9: 385991.24 | N9: 386829.69 | O9: 410769.19 | P9: 468307.18 | Q9: 4863981.2
D10: Plant Outages (002) | E10: 226478.77 | F10: 312928.05 | G10: 244993.61 | H10: 232539.09 | I10: 238807.31 | J10: 229683.42 | K10: 288539.74 | L10: 242919.9 | M10: 242366.59 | N10: 242893.06 | O10: 257924.84 | P10: 294053.34 | Q10: 3054127.7
D11: Plant Op. Costs (003) | E11: 255837.13 | F11: 353492.8 | G11: 276752.04 | H11: 262683.04 | I11: 269763.82 | J11: 259457.2 | K11: 325943.04 | L11: 274409.52 | M11: 273784.48 | N11: 274379.2 | O11: 291359.54 | P11: 332171.37 | Q11: 3450033.2
D12: Plant Admin Costs (004) | E12: 176150.15 | F12: 243388.48 | G12: 190550.59 | H12: 180863.73 | I12: 185739.02 | J12: 178642.66 | K12: 224419.8 | L12: 188937.7 | M12: 188507.35 | N12: 188916.83 | O12: 200608.21 | P12: 228708.16 | Q12: 2375432.7
C13: D) Labour Costs | D13: Labour-Costs (001) | E13: 1153364.1 | F13: 1593615.1 | G13: 1247652.6 | H13: 1184226.8 | I13: 1216148.3 | J13: 1169684.1 | K13: 1469415.4 | L13: 1237092.1 | M13: 1234274.3 | N13: 1236955.4 | O13: 1313506.1 | P13: 1497493.9 | Q13: 15553428
A14: A) Kootha Total | E14: 3458288.9 | F14: 4778353.4 | G14: 3741007.1 | H14: 3550828.8 | I14: 3646543.4 | J14: 3507223.4 | K14: 5249820.3 | L14: 4419792.7 | M14: 4409725.5 | N14: 4419304.3 | O14: 4692799.2 | P14: 5350137.2 | Q14: 51223824
A15: B) Surjek | B15: Expenses | C15: A)Chemical Costs | D15: Chem-Exp (001) | E15: 2533034.5 | F15: 3051574.2 | G15: 3084202.8 | H15: 4135202.8 | I15: 4473275.9 | J15: 3464957.9 | K15: 4049642.8 | L15: 4767948.2 | M15: 4346722.8 | N15: 4671541.1 | O15: 5478104.6 | P15: 2269805.2 | Q15: 46326013
C16: B) Facility Costs | D16: Utility-Exp (002) - Heating | E16: 1266517.3 | F16: 1525787.1 | G16: 1542101.4 | H16: 2067601.4 | I16: 2236637.9 | J16: 1732479 | K16: 2024821.4 | L16: 2383974.1 | M16: 2173361.4 | N16: 2335770.6 | O16: 2739052.3 | P16: 1134902.6 | Q16: 23163006
D17: Utility-Exp (002) - Electricity | E17: 1055431 | F17: 1271489.2 | G17: 1285084.5 | H17: 1723001.2 | I17: 1863865 | J17: 1443732.5 | K17: 1687351.2 | L17: 1986645.1 | M17: 1811134.5 | N17: 1946475.5 | O17: 2282543.6 | P17: 945752.15 | Q17: 19302505
C18: C) Operational Maintenance Costs | D18: Plant Maintenance (001) | E18: 996326.91 | F18: 1200285.8 | G18: 1213119.8 | H18: 1626513.1 | I18: 1759488.5 | J18: 1362883.5 | K18: 1592859.5 | L18: 1875393 | M18: 1709711 | N18: 1837472.8 | O18: 2154721.1 | P18: 892790.03 | Q18: 18221565
D19: Plant Outages (002) | E19: 869931.04 | F19: 1048015.4 | G19: 1059221.1 | H19: 1420170.6 | I19: 1536276.6 | J19: 785390.46 | K19: 734335.23 | L19: 864587.94 | M19: 788205.74 | N19: 847106.12 | O19: 993362.97 | P19: 514489.17 | Q19: 11461092
D20: Plant Op. Costs (003) | E20: 921103.46 | F20: 1109663.3 | G20: 1121528.3 | H20: 1503710.1 | I20: 1626645.8 | J20: 831589.9 | K20: 777531.42 | L20: 915446.06 | M20: 834570.78 | N20: 896935.9 | O20: 1051796.1 | P20: 544753.24 | Q20: 12135274
D21: Plant Admin Costs (004) | E21: 498931.04 | F21: 601067.64 | G21: 607494.48 | H21: 814509.64 | I21: 881099.8 | J21: 450444.53 | K21: 421162.85 | L21: 495866.62 | M21: 452059.17 | N21: 485840.28 | O21: 569722.88 | P21: 295074.67 | Q21: 6573273.6
C22: D) Labour Costs | D22: Labour-Costs (001) | E22: 3198275.9 | F22: 3852997.7 | G22: 3894195.4 | H22: 5221215.6 | I22: 5648075.6 | J22: 2887464.9 | K22: 2699761.9 | L22: 3178632.1 | M22: 2897815.2 | N22: 3114360.8 | O22: 3652069.7 | P22: 1891504.3 | Q22: 42136369
A23: B) Surjek Total | E23: 11339551 | F23: 13660880 | G23: 13806948 | H23: 18511924 | I23: 20025365 | J23: 12958943 | K23: 13987466 | L23: 16468493 | M23: 15013581 | N23: 16135503 | O23: 18921373 | P23: 8489071.3 | Q23: 1.793191e+08
A24: C) Jutik | B24: Expenses | C24: A)Chemical Costs | D24: Chem-Exp (001) | E24: 1625596.3 | F24: 1295067.8 | G24: 1750624.9 | H24: 1472529.4 | I24: 1252200.5 | J24: 1406782.7 | K24: 1877449.5 | L24: 1912219.2 | M24: 2266625.2 | N24: 2234200.6 | O24: 2593715.6 | P24: 2274807.8 | Q24: 21961819
C25: B) Facility Costs | D25: Utility-Exp (002) - Heating | E25: 895736.76 | F25: 713608.81 | G25: 964630.04 | H25: 811393.74 | I25: 689988.03 | J25: 775165.96 | K25: 1034513 | L25: 888365.67 | M25: 1248956.7 | N25: 680069.7 | O25: 878169.84 | P25: 1253465.5 | Q25: 10834064
D26: Utility-Exp (002) - Electricity | E26: 829385.89 | F26: 660748.9 | G26: 893175.96 | H26: 751290.5 | I26: 638877.8 | J26: 717746.26 | K26: 957882.4 | L26: 822560.8 | M26: 1156441.4 | N26: 629694.17 | O26: 813120.23 | P26: 1160616.2 | Q26: 10031541
C27: C) Operational Maintenance Costs | D27: Plant Maintenance (001) | E27: 716589.41 | F27: 570887.05 | G27: 771704.03 | H27: 649115 | I27: 551990.42 | J27: 620132.77 | K27: 827610.39 | L27: 710692.53 | M27: 999165.39 | N27: 544055.76 | O27: 702535.88 | P27: 1002772.4 | Q27: 8667251
D28: Plant Outages (002) | E28: 251329.06 | F28: 200226.94 | G28: 270659.38 | H28: 227663.79 | I28: 193599.33 | J28: 143549.25 | K28: 153261.18 | L28: 131609.73 | M28: 185030.63 | N28: 100751.07 | O28: 130099.24 | P28: 232123.24 | Q28: 2219902.8
D29: Plant Op. Costs (003) | E29: 623296.06 | F29: 496562.81 | G29: 671235.27 | H29: 564606.2 | I29: 480126.35 | J29: 356002.15 | K29: 380087.74 | L29: 326392.13 | M29: 458875.96 | N29: 249862.65 | O29: 322646.11 | P29: 575665.64 | Q29: 5505359
D30: Plant Admin Costs (004) | E30: 211116.41 | F30: 168190.63 | G30: 227353.88 | H30: 191237.58 | I30: 162623.44 | J30: 120581.37 | K30: 128739.39 | L30: 110552.17 | M30: 155425.73 | N30: 84630.897 | O30: 109283.36 | P30: 194983.52 | Q30: 1864718.4
C31: D) Labour Costs | D31: Labour-Costs (001) | E31: 3015948.7 | F31: 2402723.3 | G31: 3247912.6 | H31: 2731965.5 | I31: 2323192 | J31: 1722591 | K31: 1839134.2 | L31: 2579316.7 | M31: 2220367.5 | N31: 2209012.8 | O31: 2561190.8 | P31: 2785478.9 | Q31: 29638834
A32: C) Jutik Total | E32: 8168998.6 | F32: 6508016.3 | G32: 8797296 | H32: 7399801.7 | I32: 6292597.9 | J32: 5862551.5 | K32: 7198677.8 | L32: 7481709 | M32: 8690888.6 | N32: 6732277.6 | O32: 8110761.1 | P32: 9479913.3 | Q32: 90723489
A33: Grand Total | E33: 22966839 | F33: 24947250 | G33: 26345251 | H33: 29462555 | I33: 29964506 | J33: 22328717 | K33: 26435964 | L33: 28369995 | M33: 28114195 | N33: 27287085 | O33: 31724934 | P33: 23319122 | Q33: 3.2126641e+08

Sheet Pivot Table 2
A3: Sum of Values2 | E3: Month
A4: Account Type | B4: Unit | C4: Accounting Code Centre | D4: Accounting Code Centre Element | E4: 41456 | F4: 41487 | G4: 41518 | H4: 41548 | I4: 41579 | J4: 41609 | K4: 41640 | L4: 41671 | M4: 41699 | N4: 41730 | O4: 41760 | P4: 41791 | Q4: Grand Total
A5: Expenses | B5: Kootha | C5: Chemical Costs | D5: Chem-Exp (001) | E5: 593751.84 | F5: 820393.03 | G5: 642291.58 | H5: 609639.97 | I5: 626073.17 | J5: 602153.38 | K5: 1146144 | L5: 964931.84 | M5: 962733.96 | N5: 964825.22 | O5: 1024534.8 | P5: 1168045.2 | Q5: 10125518
B6: Surjek | C6: Chemical Costs | D6: Chem-Exp (001) | E6: 2533034.5 | F6: 3051574.2 | G6: 3084202.8 | H6: 4135202.8 | I6: 4473275.9 | J6: 3464957.9 | K6: 4049642.8 | L6: 4767948.2 | M6: 4346722.8 | N6: 4671541.1 | O6: 5478104.6 | P6: 2269805.2 | Q6: 46326013
B7: Jutik | C7: Chemical Costs | D7: Chem-Exp (001) | E7: 1625596.3 | F7: 1295067.8 | G7: 1750624.9 | H7: 1472529.4 | I7: 1252200.5 | J7: 1406782.7 | K7: 1877449.5 | L7: 1912219.2 | M7: 2266625.2 | N7: 2234200.6 | O7: 2593715.6 | P7: 2274807.8 | Q7: 21961819
A8: Water Production Actuals | B8: Kootha | C8: None | D8: None | E8: 181.93329 | F8: 187.44394 | G8: 184.77366 | H8: 191.54109 | I8: 98.096062 | J8: 185.30685 | K8: 186.90144 | L8: 158.58677 | M8: 191.40368 | N8: 171.05786 | O8: 169.287 | P8: 142.50872 | Q8: 2048.8404
B9: Surjek | C9: None | D9: None | E9: 214.969 | F9: 228.19905 | G9: 216.53647 | H9: 236.76028 | I9: 232.05286 | J9: 240.21016 | K9: 288.16055 | L9: 306.88452 | M9: 367.65101 | N9: 351.99017 | O9: 362.822 | P9: 260.3123 | Q9: 3306.5484
B10: Jutik | C10: None | D10: None | E10: 250.24199 | F10: 206.7407 | G10: 201.23546 | H10: 174.36957 | I10: 204.09105 | J10: 146.35667 | K10: 204.2025 | L10: 217.4302 | M10: 230.9822 | N10: 236.44114 | O10: 241.40737 | P10: 220.38033 | Q10: 2533.8792
A11: Grand Total | E11: 4753029.8 | F11: 5167657.4 | G11: 5477721.8 | H11: 6217974.8 | I11: 6352083.8 | J11: 5474465.9 | K11: 7073915.6 | L11: 7645782.1 | M11: 7576872 | N11: 7871326.4 | O11: 9097128.5 | P11: 5713281.4 | Q11: 78421240

Sheet Variance Analysis
A1: Budget - Actual Analysis (Variance).
A2: Why do we care about Budget Variance? In the earlier exercise, you have calculated the summarised actual costs that Southern Water Corp has incurred over the 2013 to 2014 Period. In every business, when there is an actual, a budget also exists as a counter-weight to see how accurately the business has stuck to it's budget. If the business has exceeded its budget on Revenues - that is good news. We made more than expected. However, if the business has SPENT more than it has earned or budgeted for - this is not an ideal outcome. In this Tab, we are going to ask you to calculate the Variance (Difference between Budget subtract Actuals) for Revenues, Production Costs and Other Production Costs. This is not to be confused with Statistical Variance which is a measure of dispersion. Now that we know why variance is important - let's proceed with calculating this!
A4: Q1a. Populate the Revenues Section of the Table below with the Budgeted Values from the Financial BUDGET Tab Do NOT paste the values in the Financial Budget but use Formulas to reference the Financial BUDGET Values for Kootha, Surjek And Jutik. This is because IF you simply paste - it is very easy to make mistakes which are inconsistent with the rest of the Spreadsheet.
A6: Q2a. Popuate the Production, Production Other and Overheads Section of the Table below with the Budgeted Values from the Financial Budget Tab.
A7: Budget
A8: Desalination Plants [All] | C8: 2013/Jul | D8: 2013/Aug | E8: 2013/Sep | F8: 2013/Oct | G8: 2013/Nov | H8: 2013/Dec | I8: 2014/Jan | J8: 2014/Feb | K8: 2014/Mar | L8: 2014/Apr | M8: 2014/May | N8: 2014/Jun
A9: Kootha (1 Major Desal Unit) | B9: Revenue | C9: =SUMIFS(#REF!,#REF!,'Variance Analysis'!$B9,#REF!,'Variance Analysis'!$A9) -> #REF! | D9: =SUMIFS(#REF!,#REF!,'Variance Analysis'!$B9,#REF!,'Variance Analysis'!$A9) -> #REF! | E9: =SUMIFS(#REF!,#REF!,'Variance Analysis'!$B9,#REF!,'Variance Analysis'!$A9) -> #REF! | F9: =SUMIFS(#REF!,#REF!,'Variance Analysis'!$B9,#REF!,'Variance Analysis'!$A9) -> #REF! | G9: =SUMIFS(#REF!,#REF!,'Variance Analysis'!$B9,#REF!,'Variance Analysis'!$A9) -> #REF! | H9: =SUMIFS(#REF!,#REF!,'Variance Analysis'!$B9,#REF!,'Variance Analysis'!$A9) -> #REF! | I9: =SUMIFS(#REF!,#REF!,'Variance Analysis'!$B9,#REF!,'Variance Analysis'!$A9) -> #REF! | J9: =SUMIFS(#REF!,#REF!,'Variance Analysis'!$B9,#REF!,'Variance Analysis'!$A9) -> #REF! | ... N9: =SUMIFS(#REF!,#REF!,'Variance Analysis'!$B9,#REF!,'Variance Analysis'!$A9) -> #REF!
A10: Kootha (1 Major Desal Unit) | B10: Production | C10: =SUMIFS(#REF!,#REF!,'Variance Analysis'!$B10,#REF!,'Variance Analysis'!$A10) -> #REF! | D10: =SUMIFS(#REF!,#REF!,'Variance Analysis'!$B10,#REF!,'Variance Analysis'!$A10) -> #REF! | E10: =SUMIFS(#REF!,#REF!,'Variance Analysis'!$B10,#REF!,'Variance Analysis'!$A10) -> #REF! | F10: =SUMIFS(#REF!,#REF!,'Variance Analysis'!$B10,#REF!,'Variance Analysis'!$A10) -> #REF! | G10: =SUMIFS(#REF!,#REF!,'Variance Analysis'!$B10,#REF!,'Variance Analysis'!$A10) -> #REF! | H10: =SUMIFS(#REF!,#REF!,'Variance Analysis'!$B10,#REF!,'Variance Analysis'!$A10) -> #REF! | I10: =SUMIFS(#REF!,#REF!,'Variance Analysis'!$B10,#REF!,'Variance Analysis'!$A10) -> #REF! | J10: =SUMIFS(#REF!,#REF!,'Variance Analysis'!$B10,#REF!,'Variance Analysis'!$A10) -> #REF! | ... N10: =SUMIFS(#REF!,#REF!,'Variance Analysis'!$B10,#REF!,'Variance Analysis'!$A10) -> #REF!
A11: Kootha (1 Major Desal Unit) | B11: Production Other | C11: =SUMIFS(#REF!,#REF!,'Variance Analysis'!$B11,#REF!,'Variance Analysis'!$A11) -> #REF! | D11: =SUMIFS(#REF!,#REF!,'Variance Analysis'!$B11,#REF!,'Variance Analysis'!$A11) -> #REF! | E11: =SUMIFS(#REF!,#REF!,'Variance Analysis'!$B11,#REF!,'Variance Analysis'!$A11) -> #REF! | F11: =SUMIFS(#REF!,#REF!,'Variance Analysis'!$B11,#REF!,'Variance Analysis'!$A11) -> #REF! | G11: =SUMIFS(#REF!,#REF!,'Variance Analysis'!$B11,#REF!,'Variance Analysis'!$A11) -> #REF! | H11: =SUMIFS(#REF!,#REF!,'Variance Analysis'!$B11,#REF!,'Variance Analysis'!$A11) -> #REF! | I11: =SUMIFS(#REF!,#REF!,'Variance Analysis'!$B11,#REF!,'Variance Analysis'!$A11) -> #REF! | J11: =SUMIFS(#REF!,#REF!,'Variance Analysis'!$B11,#REF!,'Variance Analysis'!$A11) -> #REF! | ... N11: =SUMIFS(#REF!,#REF!,'Variance Analysis'!$B11,#REF!,'Variance Analysis'!$A11) -> #REF!
A12: Kootha (1 Major Desal Unit) | B12: Overheads | C12: =SUMIFS(#REF!,#REF!,$A$12) -> #REF! | D12: =SUMIFS(#REF!,#REF!,$A$12) -> #REF! | E12: =SUMIFS(#REF!,#REF!,$A$12) -> #REF! | F12: =SUMIFS(#REF!,#REF!,$A$12) -> #REF! | G12: =SUMIFS(#REF!,#REF!,$A$12) -> #REF! | H12: =SUMIFS(#REF!,#REF!,$A$12) -> #REF! | I12: =SUMIFS(#REF!,#REF!,$A$12) -> #REF! | J12: =SUMIFS(#REF!,#REF!,$A$12) -> #REF! | ... N12: =SUMIFS(#REF!,#REF!,$A$12) -> #REF!
A13: Surjek (4 Major Desal. Plants) | B13: Revenue | C13: =SUMIFS(#REF!,#REF!,'Variance Analysis'!$B13,#REF!,'Variance Analysis'!$A13) -> #REF! | D13: =SUMIFS(#REF!,#REF!,'Variance Analysis'!$B13,#REF!,'Variance Analysis'!$A13) -> #REF! | E13: =SUMIFS(#REF!,#REF!,'Variance Analysis'!$B13,#REF!,'Variance Analysis'!$A13) -> #REF! | F13: =SUMIFS(#REF!,#REF!,'Variance Analysis'!$B13,#REF!,'Variance Analysis'!$A13) -> #REF! | G13: =SUMIFS(#REF!,#REF!,'Variance Analysis'!$B13,#REF!,'Variance Analysis'!$A13) -> #REF! | H13: =SUMIFS(#REF!,#REF!,'Variance Analysis'!$B13,#REF!,'Variance Analysis'!$A13) -> #REF! | I13: =SUMIFS(#REF!,#REF!,'Variance Analysis'!$B13,#REF!,'Variance Analysis'!$A13) -> #REF! | J13: =SUMIFS(#REF!,#REF!,'Variance Analysis'!$B13,#REF!,'Variance Analysis'!$A13) -> #REF! | ... N13: =SUMIFS(#REF!,#REF!,'Variance Analysis'!$B13,#REF!,'Variance Analysis'!$A13) -> #REF!
A14: Surjek (4 Major Desal. Plants) | B14: Production | C14: =SUMIFS(#REF!,#REF!,'Variance Analysis'!$B14,#REF!,'Variance Analysis'!$A14) -> #REF! | D14: =SUMIFS(#REF!,#REF!,'Variance Analysis'!$B14,#REF!,'Variance Analysis'!$A14) -> #REF! | E14: =SUMIFS(#REF!,#REF!,'Variance Analysis'!$B14,#REF!,'Variance Analysis'!$A14) -> #REF! | F14: =SUMIFS(#REF!,#REF!,'Variance Analysis'!$B14,#REF!,'Variance Analysis'!$A14) -> #REF! | G14: =SUMIFS(#REF!,#REF!,'Variance Analysis'!$B14,#REF!,'Variance Analysis'!$A14) -> #REF! | H14: =SUMIFS(#REF!,#REF!,'Variance Analysis'!$B14,#REF!,'Variance Analysis'!$A14) -> #REF! | I14: =SUMIFS(#REF!,#REF!,'Variance Analysis'!$B14,#REF!,'Variance Analysis'!$A14) -> #REF! | J14: =SUMIFS(#REF!,#REF!,'Variance Analysis'!$B14,#REF!,'Variance Analysis'!$A14) -> #REF! | ... N14: =SUMIFS(#REF!,#REF!,'Variance Analysis'!$B14,#REF!,'Variance Analysis'!$A14) -> #REF!
A15: Surjek (4 Major Desal. Plants) | B15: Production Other | C15: =SUMIFS(#REF!,#REF!,'Variance Analysis'!$B15,#REF!,'Variance Analysis'!$A15) -> #REF! | D15: =SUMIFS(#REF!,#REF!,'Variance Analysis'!$B15,#REF!,'Variance Analysis'!$A15) -> #REF! | E15: =SUMIFS(#REF!,#REF!,'Variance Analysis'!$B15,#REF!,'Variance Analysis'!$A15) -> #REF! | F15: =SUMIFS(#REF!,#REF!,'Variance Analysis'!$B15,#REF!,'Variance Analysis'!$A15) -> #REF! | G15: =SUMIFS(#REF!,#REF!,'Variance Analysis'!$B15,#REF!,'Variance Analysis'!$A15) -> #REF! | H15: =SUMIFS(#REF!,#REF!,'Variance Analysis'!$B15,#REF!,'Variance Analysis'!$A15) -> #REF! | I15: =SUMIFS(#REF!,#REF!,'Variance Analysis'!$B15,#REF!,'Variance Analysis'!$A15) -> #REF! | J15: =SUMIFS(#REF!,#REF!,'Variance Analysis'!$B15,#REF!,'Variance Analysis'!$A15) -> #REF! | ... N15: =SUMIFS(#REF!,#REF!,'Variance Analysis'!$B15,#REF!,'Variance Analysis'!$A15) -> #REF!
A16: Surjek (4 Major Desal. Plants) | B16: Overheads | C16: =SUMIFS(#REF!,#REF!,$A$16) -> #REF! | D16: =SUMIFS(#REF!,#REF!,$A$16) -> #REF! | E16: =SUMIFS(#REF!,#REF!,$A$16) -> #REF! | F16: =SUMIFS(#REF!,#REF!,$A$16) -> #REF! | G16: =SUMIFS(#REF!,#REF!,$A$16) -> #REF! | H16: =SUMIFS(#REF!,#REF!,$A$16) -> #REF! | I16: =SUMIFS(#REF!,#REF!,$A$16) -> #REF! | J16: =SUMIFS(#REF!,#REF!,$A$16) -> #REF! | ... N16: =SUMIFS(#REF!,#REF!,$A$16) -> #REF!
A17: Jutik Desalination Plant [Newest Desalination Plant] | B17: Revenue | C17: =SUMIFS(#REF!,#REF!,'Variance Analysis'!$B17,#REF!,'Variance Analysis'!$A17) -> #REF! | D17: =SUMIFS(#REF!,#REF!,'Variance Analysis'!$B17,#REF!,'Variance Analysis'!$A17) -> #REF! | E17: =SUMIFS(#REF!,#REF!,'Variance Analysis'!$B17,#REF!,'Variance Analysis'!$A17) -> #REF! | F17: =SUMIFS(#REF!,#REF!,'Variance Analysis'!$B17,#REF!,'Variance Analysis'!$A17) -> #REF! | G17: =SUMIFS(#REF!,#REF!,'Variance Analysis'!$B17,#REF!,'Variance Analysis'!$A17) -> #REF! | H17: =SUMIFS(#REF!,#REF!,'Variance Analysis'!$B17,#REF!,'Variance Analysis'!$A17) -> #REF! | I17: =SUMIFS(#REF!,#REF!,'Variance Analysis'!$B17,#REF!,'Variance Analysis'!$A17) -> #REF! | J17: =SUMIFS(#REF!,#REF!,'Variance Analysis'!$B17,#REF!,'Variance Analysis'!$A17) -> #REF! | ... N17: =SUMIFS(#REF!,#REF!,'Variance Analysis'!$B17,#REF!,'Variance Analysis'!$A17) -> #REF!
A18: Jutik Desalination Plant [Newest Desalination Plant] | B18: Production | C18: =SUMIFS(#REF!,#REF!,'Variance Analysis'!$B18,#REF!,'Variance Analysis'!$A18) -> #REF! | D18: =SUMIFS(#REF!,#REF!,'Variance Analysis'!$B18,#REF!,'Variance Analysis'!$A18) -> #REF! | E18: =SUMIFS(#REF!,#REF!,'Variance Analysis'!$B18,#REF!,'Variance Analysis'!$A18) -> #REF! | F18: =SUMIFS(#REF!,#REF!,'Variance Analysis'!$B18,#REF!,'Variance Analysis'!$A18) -> #REF! | G18: =SUMIFS(#REF!,#REF!,'Variance Analysis'!$B18,#REF!,'Variance Analysis'!$A18) -> #REF! | H18: =SUMIFS(#REF!,#REF!,'Variance Analysis'!$B18,#REF!,'Variance Analysis'!$A18) -> #REF! | I18: =SUMIFS(#REF!,#REF!,'Variance Analysis'!$B18,#REF!,'Variance Analysis'!$A18) -> #REF! | J18: =SUMIFS(#REF!,#REF!,'Variance Analysis'!$B18,#REF!,'Variance Analysis'!$A18) -> #REF! | ... N18: =SUMIFS(#REF!,#REF!,'Variance Analysis'!$B18,#REF!,'Variance Analysis'!$A18) -> #REF!
A19: Jutik Desalination Plant [Newest Desalination Plant] | B19: Production Other | C19: =SUMIFS(#REF!,#REF!,'Variance Analysis'!$B19,#REF!,'Variance Analysis'!$A19) -> #REF! | D19: =SUMIFS(#REF!,#REF!,'Variance Analysis'!$B19,#REF!,'Variance Analysis'!$A19) -> #REF! | E19: =SUMIFS(#REF!,#REF!,'Variance Analysis'!$B19,#REF!,'Variance Analysis'!$A19) -> #REF! | F19: =SUMIFS(#REF!,#REF!,'Variance Analysis'!$B19,#REF!,'Variance Analysis'!$A19) -> #REF! | G19: =SUMIFS(#REF!,#REF!,'Variance Analysis'!$B19,#REF!,'Variance Analysis'!$A19) -> #REF! | H19: =SUMIFS(#REF!,#REF!,'Variance Analysis'!$B19,#REF!,'Variance Analysis'!$A19) -> #REF! | I19: =SUMIFS(#REF!,#REF!,'Variance Analysis'!$B19,#REF!,'Variance Analysis'!$A19) -> #REF! | J19: =SUMIFS(#REF!,#REF!,'Variance Analysis'!$B19,#REF!,'Variance Analysis'!$A19) -> #REF! | ... N19: =SUMIFS(#REF!,#REF!,'Variance Analysis'!$B19,#REF!,'Variance Analysis'!$A19) -> #REF!
A20: Jutik Desalination Plant [Newest Desalination Plant] | B20: Overheads | C20: =SUMIFS(#REF!,#REF!,$A$20) -> #REF! | D20: =SUMIFS(#REF!,#REF!,$A$20) -> #REF! | E20: =SUMIFS(#REF!,#REF!,$A$20) -> #REF! | F20: =SUMIFS(#REF!,#REF!,$A$20) -> #REF! | G20: =SUMIFS(#REF!,#REF!,$A$20) -> #REF! | H20: =SUMIFS(#REF!,#REF!,$A$20) -> #REF! | I20: =SUMIFS(#REF!,#REF!,$A$20) -> #REF! | J20: =SUMIFS(#REF!,#REF!,$A$20) -> #REF! | ... N20: =SUMIFS(#REF!,#REF!,$A$20) -> #REF!
